Workbook

Sheet Home
A1: THIS DOCUMENT WILL BE DEPRECATED BY THE END OF APRIL 2025 If you need support please submit a ticket via zendesk.
F5: RESULTS | I5: Share this document: https://bit.ly/FundedProjectsReporting
C6: Date Launched | D6: 1st Funding | E6: Launch Guide | F6: Official Results (PDF) | G6: Sheets Output (excel)
B7: Fund1 (pilot) | C7: Aug 2020 | D7: n/a | E7: n/a | F7: https://drive.google.com/file/d/1UmAGBRxWbQtpWjrNnvGuybgLiWs2zFMS/view | G7: n/a
B8: Fund2 | C8: Sep 2020 | D8: Jan 2021 | E8: n/a | F8: https://static.iohk.io/docs/catalyst/catalyst-voting-results-fund2.pdf | G8: n/a
B9: Fund3 | C9: Jan 2021 | D9: Apr 2021 | E9: n/a | F9: https://drive.google.com/file/d/1X6BnuFBvNO8yF2DeUgBqA3yyYSvqeKvg/view | G9: https://docs.google.com/spreadsheets/d/1ibl-9qpLRQiFhJQfcvIeSdfJr9LjGpU6WqHce6VIUnE/edit#gid=1538672709
B10: Fund4 | C10: Feb 2021 | D10: July 2021 | E10: n/a | F10: https://drive.google.com/file/d/19VMTYn_sv5Xsp2mC5VUN_-z_aXYHL_Dd/view | G10: https://docs.google.com/spreadsheets/d/13NC6SZ5MzQsYb-ufbuQHakxvLvPtZWv_02Aq17PFErI/edit#gid=1538672709
B11: Fund5 | C11: Mar 2021 | D11: Aug 2021 | E11: n/a | F11: https://drive.google.com/file/d/1HKmqyPebE87BUrPtE4AT5E2V4_yIZtT-/view | G11: https://docs.google.com/spreadsheets/d/156SdqPYOBkC5iQQeOOZc9yXSYoNHb-J-wJrem-xax78/edit#gid=1848314097
B12: Fund6 | C12: Aug 2020 | D12: Nov 2021 | E12: https://drive.google.com/file/d/1-8rQ4KBVJmCuS4MYLevryZFHicip97sH/view | F12: https://drive.google.com/file/d/13h5JFtwqyylMUNMoRGXQZ-FJEM4bznOJ/view?usp=sharing | G12: https://docs.google.com/spreadsheets/d/1y-7U88FRvsEEzm98KbEswUGuy4q-eTeoFTV3EFrc6b4/edit#gid=1183771745
B13: Fund7 | C13: Nov 2021 | D13: Feb 2022 | E13: https://drive.google.com/file/d/1E47HUA9Xikla1v9bvgxw-pR3_4kSnTye/view | F13: https://bit.ly/3HJNhuX | G13: https://docs.google.com/spreadsheets/d/19_TEovS_Gemwvz2qlc6jGPizqAY8ZeDrzbH3DSeXyto/edit#gid=309291557
B14: Fund8 | C14: Feb 2022 | D14: May 2022 | E14: https://bit.ly/3LDYNuk | F14: https://drive.google.com/file/d/1s3jCE7pmoUujy3ASMia-UhFl2KLi_hnf/view | G14: https://docs.google.com/spreadsheets/d/15ELXp81NfvXHgrerTbuIofZOXBsdjocN1YgBK0gPP3E/edit#gid=2111315347
B15: Fund9 | C15: Jun 2022 | D15: Oct 2022 | E15: https://bit.ly/Fund9-Launch-Guide | F15: https://bit.ly/Fund9_Results | G15: https://docs.google.com/spreadsheets/d/1MycQL-dkqf1xEW8xcr7vqcfHY6D7MHnG9ylDKNLSnAA/edit?usp=sharing
B16: Fund10
B17: Fund11
B18: Fund12
B19: Fund13
B20: MIRO | D20: https://bit.ly/3wiBHjP
B22: Each Funded Project is expected to submit one reporting form each month. If this form is missing - funding is paused until it is completed. You can track progress via individual tabs in this document.
B25: Monthly Report Form: | C25: https://bit.ly/CatalystMonthlyReport
B26: Monthly Report Output | C26: https://bit.ly/Funded-Projects-Reports
B28: Final Close Out Report & Video | I28: Browse All Projects
B29: Is your project nearing completion or has already completed? Please reach out to catalyst (at) iohk.io directly to request the close out process to be intiated. If done properly, your project will be marked as COMPLETED on this tracker including link to your final reports. Do you not see your project reporting anymore? Perhaps they've also completed. Reach out to them directly to inspire them to share close out reports with the rest of the community officially. | H29: projectcatalyst.io
B30: Close Out Report Form: | C30: https://bit.ly/3XgkPZr
B32: Contact for Qs: via email catalyst (at) iohk.io
B34: LEGEND:
B35: PENDING | C35: Project is currently under way executing on their deliverables
B36: COMPLETED | C36: Project has completed their scope of delivery based on their voted proposal and are now offboarded from reporting requirements
B37: PAUSED | C37: Project ran into an issue, reached out and decided to pause their operations until further notice - funding also pauses
B39: Note: This is not a real time dashboard. Consider it as a continous work in progress (WIP) and minimum viable product (MVP) as data can change as new input is available. Information is provided as in and does not constitute an investment advice or otherwise. Any feedback or further suggestions how to improve are more than welcome. Is there something you think would bring value to measure/track, let us know. Think about where our attention needs to be. Comment directly in this document or reach out to us Note: ROI dashboard is one of the 2022 goals to tackle! .

Sheet COMPLETED
A1: THIS DOCUMENT WILL BE DEPRECATED SOON If you need support please submit a ticket via zendesk.
C5: Updated: 23 February 2026 | D5: Project Completions | F5: Funding ($) | M5: Mandatory TH pres (preceeding close out reports) | O5: Mandatory Close Outs (since Nov 2021)
B6: # | C6: Project ID# | D6: Project Name (original proposal hyperlink) | E6: Project Status | F6: Requested | G6: Distributed to date | H6: Remaining | I6: Primary Proposer - Guarantor | J6: Fund # | K6: Challenge Category | L6: Date Completed | M6: Final TH Pres | N6: Final TH Video | O6: Final Close Out Report | P6: Final Close Out Video | Q6: Submitted Close Out Video
D7: ='Summary (draft)'!G6 -> 1581 | F7: =SUM(F8:F2729) -> 1.452159e+08 | G7: =SUM(G8:G2729) -> 1.4157987e+08 | H7: =SUM(H8:H2729) -> 3636029.7
B8: 1 | C8: 200003 | D8: Create message signing standard | E8: COMPLETED | F8: 5000 | G8: 5000 | H8: =F8-G8 -> 0 | I8: Sebastien Guillemot | J8: Fund2 | K8: Developer ecosystem | L8: 44287 | M8: https://docs.google.com/presentation/d/1CCkVN0jNpEBZjzjVWkrft2XBxNH2U8NwxvaZdOwRxIY/edit#slide=id.ge8e7e12b51_0_8915 | N8: https://youtu.be/C1pcZWFqAV8?t=898 | O8: n/a | Q8: n/a
B9: 2 | C9: 200010 | D9: Ouroboros over RINA | E9: COMPLETED | F9: 10700 | G9: 10700 | H9: =F9-G9 -> 0 | I9: Jason Durham | J9: Fund2 | K9: Developer ecosystem | L9: 44287 | M9: https://docs.google.com/presentation/d/1DwyQEluti2WMnKAF4KxJS9gnJwM0yIy4PVKj4yzvq7U/edit#slide=id.gd0bd6b1465_0_0 | N9: https://www.youtube.com/watch?v=n4d5iXuEeuo | O9: n/a | Q9: n/a
B10: 3 | C10: 500063 | D10: Testnet Cardanoscan Explorer | E10: COMPLETED | F10: 7500 | G10: 7500 | H10: =F10-G10 -> 0 | I10: Ashish Prajapati | J10: Fund5 | K10: Developer Ecosystem | L10: 44409 | M10: https://docs.google.com/presentation/d/1CCkVN0jNpEBZjzjVWkrft2XBxNH2U8NwxvaZdOwRxIY/edit#slide=id.ge8e7e12b51_0_6235 | N10: https://youtu.be/C1pcZWFqAV8?t=541 | O10: n/a | Q10: n/a
B11: 4 | C11: 300004 | D11: Cardano IntelliJ IDEA Plugin (MVP) | E11: COMPLETED | F11: 15000 | G11: 15000 | H11: =F11-G11 -> 0 | I11: Satya Ranjan | J11: Fund3 | K11: Developer ecosystem | L11: 44440 | M11: https://docs.google.com/presentation/d/1Xi8COzkjn7vINiWNnSRay0as2nyrHNRLkng_oh8JYzU/edit#slide=id.geb801ec31f_1_13938 | N11: https://drive.google.com/file/d/1vgbwTL76_esvtuzEP_BOPTA66DXyqr-j/view | O11: n/a | Q11: n/a
B12: 5 | C12: 300006 | D12: CardanoSharp - .NET Library | E12: COMPLETED | F12: 19520 | G12: 19520 | H12: =F12-G12 -> 0 | I12: Kyle Johns | J12: Fund3 | K12: Developer ecosystem | L12: 44440 | M12: https://docs.google.com/presentation/d/1_BGhCFyPgpzoHmx_wuHcskOWDAQYU9pcVu0XXYCV6g4/edit#slide=id.gef920b8573_0_11 | N12: https://drive.google.com/file/d/1VBaPGjOLOKK_3CYlU6Y5JUqsP03P-Mtb/view | O12: n/a | Q12: n/a
B13: 6 | C13: 400049 | D13: West Africa Proposer Outreach | E13: COMPLETED | F13: 6000 | G13: 6000 | H13: =F13-G13 -> 0 | I13: Josh Fielding | J13: Fund4 | K13: Proposer Outreach | L13: 44440 | M13: https://docs.google.com/presentation/d/1-2GfEnkkK01bp3KzbAVKb7nW6LYXkTOrIZ0qVvNTs9k/edit#slide=id.gef920b8573_0_11 | N13: https://youtu.be/7_171-XgPdI?t=161 | O13: n/a | Q13: n/a
B14: 7 | C14: 200001 | D14: Address Gap in SPO Education/Comms | E14: COMPLETED | F14: 10700 | G14: 10700 | H14: =F14-G14 -> 0 | I14: Ron Hill | J14: Fund2 | K14: n/a | L14: 44440 | M14: n/a | N14: n/a | O14: https://drive.google.com/file/d/17Ac02cFF5YX2VWIYyki-XIJU5S0ORJ-M/view?usp=sharing
B15: 8 | C15: 400019 | D15: Guided Onboarding Experience | E15: COMPLETED | F15: 15000 | G15: 15000 | H15: =F15-G15 -> 0 | I15: Michael McNulty | J15: Fund4 | K15: Catalyst Value Onboarding | L15: 44440 | M15: n/a | N15: n/a | O15: https://drive.google.com/file/d/10JQGY9I-_mvjjfAAfKdyoEUlu2zs0Gpi/view?usp=sharing | P15: https://youtu.be/GcIlwjjnSwI | Q15: https://www.youtube.com/watch?v=0rh_IggFq_A
B16: 9 | C16: 400012 | D16: Cardano-based Marketplace | E16: COMPLETED | F16: 5000 | G16: 5000 | H16: =F16-G16 -> 0 | I16: Michael Parkinson | J16: Fund4 | K16: dApps & Integrations | L16: 44440 | M16: n/a | N16: n/a | O16: https://drive.google.com/file/d/1QLhnoaS5e_sQeYOZ7GAXIUJWdLSXlaRv/view?usp=sharing | P16: https://youtu.be/NA3e3CkFtno | Q16: https://drive.google.com/file/d/1MO883gsGSH0_79hYf19kuTxGGInboRV7/view?usp=sharing
B17: 10 | C17: 300020 | D17: Visual Studio Smart Contract Plugin | E17: COMPLETED | F17: 16450 | G17: 16450 | H17: =F17-G17 -> 0 | I17: Rob Greig | J17: Fund3 | K17: Developer ecosystem | L17: 44470 | M17: https://docs.google.com/presentation/d/1R40XA9w3hdogAkcDJNpL3gM3S9q8pcTIQYCokrEow8s/edit#slide=id.gf9a9b45fbc_0_5002 | N17: https://youtu.be/VudbBWPh-qA?t=2108 | O17: n/a | Q17: n/a
B18: 11 | C18: 400007 | D18: Cardano China Info Hub | E18: COMPLETED | F18: 16700 | G18: 16700 | H18: =F18-G18 -> 0 | I18: Bullish Dumpling | J18: Fund4 | K18: Local Community Centers | L18: 44470 | M18: https://docs.google.com/presentation/d/1KHx-tID5RdWyoXitLQpdf2Ti3EgSF9RjilC8_-jJWwk/edit#slide=id.gf69e0ccf0f_1_2387 | N18: https://youtu.be/yts3EFEODtU?t=240 | O18: n/a | Q18: n/a
B19: 12 | C19: 400032 | D19: NFT-DAO NFT metadata standards | E19: COMPLETED | F19: 28648 | G19: 28648 | H19: =F19-G19 -> 0 | I19: Rich Kopcho | J19: Fund4 | K19: DApps & Integrations | L19: 44470 | M19: n/a | N19: n/a | O19: https://drive.google.com/file/d/1leCReF4Qyhk-1sUm7tzIY59kx78UDRtJ/view?usp=sharing | Q19: https://drive.google.com/file/d/1CHVVhAO8cisL9G-bAw656C3Es7tVN1kF/
B20: 13 | C20: 400003 | D20: Adagov.org (Co-creation) | E20: COMPLETED | F20: 8000 | G20: 8000 | H20: =F20-G20 -> 0 | I20: Ro Mathew | J20: Fund4 | K20: Distributed Decision Making | L20: 44470 | M20: n/a | N20: n/a | O20: https://drive.google.com/file/d/1IpZexVamBRg4mWtrxmK5ZmEIXJj7Tv-K/view?usp=sharing | P20: https://youtu.be/udkz_JBKPEM | Q20: https://drive.google.com/file/d/1qfOaLzw46exfNMLeBH8uIamLnKo53yG5/view?usp=sharing
B21: 14 | C21: 500060 | D21: Quality-Assurance-DAO | E21: COMPLETED | F21: 5 | G21: 5 | H21: =F21-G21 -> 0 | I21: Stephen Whitenstall | J21: Fund5 | K21: Developer Ecosystem | L21: 44501 | M21: https://docs.google.com/presentation/d/11StNCcf4sBhWAgWKL7kWLK1adfXg7i9dd2i7KWgrY8U/edit#slide=id.g1050bd8c40a_0_8840 | N21: https://youtu.be/olOxEinXrgM?t=1402 | Q21: n/a
B22: 15 | C22: 400014 | D22: Diversify Voting Influence | E22: COMPLETED | F22: 14000 | G22: 14000 | H22: =F22-G22 -> 0 | I22: Kenric Nelson | J22: Fund4 | K22: Distributed Decision Making | L22: 44501 | M22: https://docs.google.com/presentation/d/1R40XA9w3hdogAkcDJNpL3gM3S9q8pcTIQYCokrEow8s/edit#slide=id.gf9a9b45fbc_0_10242 | N22: https://youtu.be/VudbBWPh-qA?t=1082 | O22: https://docs.google.com/document/d/147av_tt9p1UgtWemZTJ7uTLrF706PaLBYTw__juwTAE/edit?usp=sharing | P22: https://youtu.be/pfboXRFkucQ | Q22: https://drive.google.com/file/d/1NY20WHgY1YLR32D3TP1v5LyD5zUvUPd1/view
B23: 16 | C23: 500056 | D23: Paper wallet terminal for in a shop | E23: COMPLETED | F23: 12000 | G23: 12000 | H23: =F23-G23 -> 0 | I23: Maarten Menheere | J23: Fund5 | K23: Grow Africa, Grow Cardano | L23: 44501 | M23: https://docs.google.com/presentation/d/10Xk7dbkuSveM0oJefMzTbZqsniikn0Hoe-Rtgx3v8oI/edit#slide=id.gf69e0ccf0f_1_4675 | N23: https://youtu.be/Pw6VdcWi8NE?t=1067 | O23: https://drive.google.com/file/d/1Bt2ZoWSZspJ7dHyw2ZkKgcz4kE7_P-VQ/view?usp=sharing | P23: https://youtu.be/-WTyBVomdtQ | Q23: https://drive.google.com/file/d/1ou8Jsv4-1nOdGJLo5AQ9zQtJ7oLqCmNE/view?%20usp=sharing
B24: 17 | C24: 500068 | D24: WADA Uni Students Catalyst Registry | E24: COMPLETED | F24: 11000 | G24: 11000 | H24: =F24-G24 -> 0 | I24: Mercy Tachie-Menson | J24: Fund5 | K24: Catalyst Value Onboarding | L24: 44501 | M24: n/a | N24: n/a | O24: https://docs.google.com/document/d/1-cZa5MVgX9oJv-gVEVTHsxsd6grd1pe-7nTZVmQJexM/edit?usp=sharing | P24: https://youtu.be/txmgKUFpK6E | Q24: https://drive.google.com/file/d/1u1WjH-eapdgNh9827NfiIoO4GPRtVmzD/view?usp=drive_web
B25: 18 | C25: 400030 | D25: Local Centers in West Africa | E25: COMPLETED | F25: 4000 | G25: 4000 | H25: =F25-G25 -> 0 | I25: Mercy Tachie-Menson | J25: Fund4 | K25: Local Community Centers | L25: 44501 | M25: n/a | N25: n/a | O25: https://docs.google.com/document/d/1-cZa5MVgX9oJv-gVEVTHsxsd6grd1pe-7nTZVmQJexM/edit?usp=sharing | P25: https://youtu.be/IScHE-goK5I | Q25: https://drive.google.com/file/d/1u1WjH-eapdgNh9827NfiIoO4GPRtVmzD/view?usp=drive_web
B26: 19 | C26: 600042 | D26: Community Subscription Fees Recoup | E26: COMPLETED | F26: 581 | G26: 581 | H26: =F26-G26 -> 0 | I26: Steven Aldrich | J26: Fund6 | K26: Catalyst value onboarding | L26: 44501 | M26: n/a | N26: n/a | O26: https://drive.google.com/file/d/1-74_XPCfxDxiOdSn1bUJevlqWsObKkgU/view?usp=sharing | Q26: n/a
B27: 20 | C27: 600084 | D27: Indigo: Synthetic Assets on Cardano | E27: COMPLETED | F27: 60000 | G27: 60000 | H27: 0 | I27: Daniel Short | J27: Fund6 | K27: Atala PRISM DID Mass-Scale Adoption | L27: 44531 | M27: https://docs.google.com/presentation/d/11StNCcf4sBhWAgWKL7kWLK1adfXg7i9dd2i7KWgrY8U/edit#slide=id.g1050bd8c40a_0_6160 | N27: https://youtu.be/olOxEinXrgM?t=328 | O27: https://docs.google.com/document/d/1474INdXZI_EKguvPH3GssQEVM5zdxdz-b4KsraW5JKM/edit?usp=sharing | P27: https://youtu.be/UO91GPqxRpc | Q27: https://drive.google.com/file/d/1YXk8ClEIq4TamUdgB5_SausWNr40h7CI/view?usp=sharing
B28: 21 | C28: 600005 | D28: Add multilanguage to CNFTHub.io | E28: COMPLETED | F28: 500 | G28: 500 | H28: 0 | I28: Huth Solo | J28: Fund6 | K28: Scale-UP Cardano's Community Hubs | L28: 44531 | M28: n/a | N28: n/a | O28: https://docs.google.com/document/d/17w8yN7niNrdGTfB2qk5BquPSVGDk7BHL/edit?usp=sharing&ouid=117059928304090739258&rtpof=true&sd=true | P28: https://youtu.be/sntE2N2qNr4 | Q28: https://youtu.be/SJ_8tQLhyms
B29: 22 | C29: 500006 | D29: Artificial Intelligence/ML API | E29: COMPLETED | F29: 80000 | G29: 80000 | H29: =F29-G29 -> 0 | I29: Javier Paz | J29: Fund5 | K29: Developer Ecosystem | L29: 44531 | M29: n/a | N29: n/a | O29: https://drive.google.com/file/d/1GYbtCl7bPLhPLVaxl08jfOC2i6NTf34D/view?usp=sharing | P29: https://youtu.be/RYuj_wj0nQ4 | Q29: https://youtu.be/iSKDxZH5Vyc
B30: 23 | C30: 500032 | D30: Glow Formal verification | E30: COMPLETED | F30: 60000 | G30: 60000 | H30: =F30-G30 -> 0 | I30: Alexander Smart | J30: Fund5 | K30: Developer Ecosystem | L30: 44531 | M30: n/a | N30: n/a | O30: https://drive.google.com/file/d/1aNPkbKSBdos5swJGgRj00NmQ6N1Tpvyq/view?usp=sharing | P30: https://youtu.be/Xr1MnlaFKM4 | Q30: https://youtu.be/YSvkNDgFbYg
B31: 24 | C31: 300007 | D31: Comprehensive NFT Framework Collab | E31: COMPLETED | F31: 48965 | G31: 48965 | H31: =F31-G31 -> 0 | I31: Rich Kopcho | J31: Fund3 | K31: DApp creation | L31: 44531 | M31: n/a | N31: n/a | O31: https://drive.google.com/file/d/1FqRIxooA_5OpU_EfyvpRat0Qdur2ZWZF/view?usp=sharing | P31: https://youtu.be/KY1c-0dP4zg | Q31: https://youtu.be/i5jOwWzljk4
B32: 25 | C32: 600017 | D32: Books for Blocks | E32: COMPLETED | F32: 600 | G32: 600 | H32: =F32-G32 -> 0 | I32: williamofthesun | J32: Fund6 | K32: Partnerships for Global Adoption | L32: 44531 | M32: n/a | N32: n/a | O32: https://drive.google.com/file/d/14wyU2EaXDs-yCIZut7AafG03mGmnSmCl/view?usp=sharing | P32: https://youtu.be/V6HCIxSqpkU | Q32: https://drive.google.com/file/d/1s19rPZSZrd_rZoImJt9i_1F2G6xVs3Fm/view?usp=sharing
B33: 26 | C33: 500065 | D33: Tokenizing GitHub Pull request | E33: COMPLETED | F33: 12000 | G33: 12000 | H33: =F33-G33 -> 0 | I33: Max Bin Li | J33: Fund5 | K33: Developer Ecosystem | L33: 44531 | M33: n/a | N33: n/a | O33: https://drive.google.com/file/d/1_qFSfFiUWt_IwVjkkDRehRRi2wMUOiSy/view?usp=sharing | P33: https://youtu.be/65UuqD0HTHw | Q33: https://drive.google.com/file/d/1E_-B4AbpSH-rnnvUFsm1xTSNfGpz3wzJ/view
B34: 27 | C34: 500038 | D34: Introducing Empowa | E34: COMPLETED | F34: 60000 | G34: 60000 | H34: =F34-G34 -> 0 | I34: Phil Lewis | J34: Fund5 | K34: Grow Africa, Grow Cardano | L34: 44531 | M34: n/a | N34: n/a | O34: https://drive.google.com/file/d/12D40OuAK3Wi1croI4WhNH-yDxIOgJQ9w/view?usp=sharing | P34: https://youtu.be/2E1BbSdxDMk | Q34: https://youtu.be/5qCnVTKZNuc
B35: 28 | C35: 600026 | D35: Cardano Wallet JS Multisig | E35: COMPLETED | F35: 4800 | G35: 4800 | H35: =F35-G35 -> 0 | I35: Leobel Izquierdo | J35: Fund6 | K35: Developer ecosystem | L35: 44562 | M35: n/a | N35: n/a | O35: https://drive.google.com/file/d/133GxLWHBIxVx_1Tj1M7ydJdmMWgcgdzM/view?usp=sharing | P35: https://youtu.be/NxsSRQgSDE0 | Q35: https://www.youtube.com/watch?v=H7O4b_PtQ-8&t=41s
B36: 29 | C36: 200004 | D36: GimbaLabs (Cardano Starter Kits & APIs) | E36: COMPLETED | F36: 28355 | G36: 28355 | H36: =F36-G36 -> 0 | I36: Juliane Montag | J36: Fund2 | K36: n/a | L36: 44593 | M36: https://docs.google.com/spreadsheets/d/1bfnWFa94Y7Zj0G7dtpo9W1nAYGovJbswipxiHT4UE3g/edit#gid=416498551 | N36: https://youtu.be/PELxvpPWuYk?t=285 | O36: https://drive.google.com/file/d/1BWUA29-O_mbhIT-KhXP-9G-wBAMKIQmL/view?usp=sharing | P36: https://youtu.be/8MauHjTKtGY | Q36: https://drive.google.com/file/d/1mvZ43cGM2y1HtYAAlHNzowerM_qdmf3u/view?usp=sharing
B37: 30 | C37: 500057 | D37: PCDiscord - Bot to Assign Roles | E37: COMPLETED | F37: 500 | G37: 500 | H37: =F37-G37 -> 0 | I37: Tevo Saks | J37: Fund5 | K37: Catalyst Value Onboarding | L37: 44593 | M37: n/a | N37: n/a | O37: https://drive.google.com/file/d/1KK2mFMz4HYyTDZpOZEEiUhnNZY90LE72/view?usp=sharing | P37: https://youtu.be/IoBnqIzjetc | Q37: https://youtu.be/QhEbdpPq5Q0
B38: 31 | C38: 600095 | D38: Mini Proposals as a Service | E38: COMPLETED | F38: 1404 | G38: 1404 | H38: =F38-G38 -> 0 | I38: Tevo Saks | J38: Fund6 | K38: DLT Entrepreneurship Toolbox | L38: 44593 | M38: n/a | N38: n/a | O38: https://drive.google.com/file/d/1296-tef_bbg4LL_kSwHOqPZxN6v6VoVe/view?usp=sharing | P38: https://youtu.be/YQ0sdE2OhOE | Q38: https://youtu.be/EZBnaFt9BPk
B39: 32 | C39: 600051 | D39: Crypto Regulation Surveillance | E39: COMPLETED | F39: 9000 | G39: 9000 | H39: =F39-G39 -> 0 | I39: Maury Shenk | J39: Fund6 | K39: F6: Cardano Emerging Threat Alarm | L39: 44593 | M39: n/a | N39: n/a | O39: https://drive.google.com/file/d/128BeS_xJaO3Ftv9DGVrJ-5GQIgUYXL55/view?usp=sharing | P39: https://youtu.be/040pfxj-xXs | Q39: https://youtu.be/9DHT5mogILo
B40: 33 | C40: 600011 | D40: API for Multi-Delegation Portfolios | E40: COMPLETED | F40: 10000 | G40: 10000 | H40: =F40-G40 -> 0 | I40: viperstakepool | J40: Fund6 | K40: DApps & Integrations | L40: 44593 | M40: n/a | N40: n/a | O40: https://drive.google.com/file/d/1rphX1xB8q9ViUC0rjt0y-FQIn8A-WKb2/view?usp=sharing | P40: https://youtu.be/zV_ZNI74Nhc | Q40: https://youtu.be/2iWbNCLkHMY
... B48: 41 | C48: 600078 | D48: Gravatar for ADA Wallets | E48: COMPLETED | F48: 87700 | G48: 87700 | H48: =F48-G48 -> 0 | I48: Matthias Sieber | J48: Fund6 | K48: Developer ecosystem | L48: 44593 | M48: n/a | N48: n/a | O48: https://drive.google.com/file/d/1oJwqPYBGvh6yO8RU9eIoSErtecChRA-J/view?usp=sharing | P48: https://youtu.be/p-9fwgygrqI | Q48: https://drive.google.com/file/d/1DpUZsPfEzgSK_XGJIbv6DKU53Gjr0BIS/view?usp=sharing
B49: 42 | C49: 700061 | D49: Catalyst Circle Treasury Management | E49: COMPLETED | F49: 11400 | G49: 11400 | H49: =F49-G49 -> 0 | I49: Miroslav Rajh | J49: Fund7 | K49: Miscellaneous Challenge | L49: 44593 | M49: n/a | N49: n/a | O49: https://drive.google.com/file/d/1S3Ktje_yL8Wu8U1KED8VhPGP3r-Qy88g/view?usp=sharing | Q49: https://drive.google.com/drive/folders/1HsTq52QWP6UlWbHO4ZzBFxsIrvysCjNL
B50: 43 | C50: 500062 | D50: Step-by-Step Guide: Off-Chain Code | E50: COMPLETED | F50: 5000 | G50: 5000 | H50: =F50-G50 -> 0 | I50: Michael Parkinson | J50: Fund5 | K50: Developer Ecosystem | L50: 44621 | M50: n/a | N50: n/a | O50: https://drive.google.com/file/d/1WzqMZjJRU0MUXSecuFWnyPTT1SCyjt71/view?usp=sharing | P50: https://youtu.be/2kQiTy-jiJo | Q50: https://www.youtube.com/watch?v=o1UEkVhiAs4
...

Sheet Monthly TXs
B1: Distribution # | C1: Actual date | D1: Telegram Announcement | E1: Fund4 (tx id) | F1: Fund5 (tx id) | G1: Fund6 (tx id) | H1: Fund7 (tx id) | I1: Fund8 (tx id) | J1: Fund9 (tx id) | K1: Fund10 (tx id) | L1: Fund11 (tx id) | M1: Fund12 (tx id) | N1: Fund13 (tx id) | O1: Fund14 (tx id)
A2: 2023 | B2: October #1 | C2: 45208 | D2: https://t.me/c/1522687916/340 | F2: 9198dedcaf2793604a94d9d512c324194a7278315341a2f3ee5432d9ef5ce2a5 | G2: c2e58a716887d0a558b3d9fc18911293d1685a5014d90f0fdddcbfb283f15f5a | H2: 234a75d2202bac3c2364d291c0509c03f1a0b2d3f0c2ea58a0caaa13afdce28f | I2: ea073131bdaa5cad85d5af0f23c447fc06db1a457eb17d914cfb961bbc4eeb61 | J2: 07e44d0e0dc15747c021b8ef0929f8efaa71275ef234b80aba9a7ac3f16be918
B3: October #2 | C3: 45215 | D3: https://t.me/c/1522687916/344 | K3: 374aa9c45ec5b379b66b170939e9d70070ec3f4c012bb1ed3bda7cf8edec5cd0
B4: October #3 | C4: 45222 | D4: https://t.me/c/1522687916/347 | K4: b3b3fbea76297dd7d6d6c5830afb5fcf3f51cb498c7a4a7884b9a72c9d0742a1
B5: October #4 | C5: 45229 | D5: https://t.me/c/1522687916/349 | H5: 2af879b5a06c8ace266fe79e0c5394058a24f8accadda2f5ca73ca1a84e2264b | I5: 212696c539b76d5c9872f6fb9706fc4f6bbd7b2236a3706dae4d3493a2c106f5 | J5: f5756244a79525c73421e5796779fdda79b00cd24eb25aea4f2413cf6d948ff3 | K5: 44e7dff4601cfe0388a660f486e25fe8d6cf65f2dbc0b3f73dc30ed1bfcfc443
B6: November #1 | C6: 45243 | D6: https://t.me/c/1522687916/356 | H6: 022b4faf3c4c7c1d0b3e5c2eec2954e7fc2eb160ab16c12c38397478da3e2850 | I6: 9119a85b164a0a6dde31b045a5f535c7ec9e72d1e7d4bad628d65027121d12f9 | J6: dc8820a2766ba60f2bf6a752cf8c8efc811fb5b2bcaf40cd99a8b99bcf4d60b6 | K6: 3fd7990db5f25dc63e7abf2d28e74f7bbd76d7930d6eeaae90fd8320b3c4b1e9
B7: November #2 | C7: 45257 | D7: https://t.me/c/1522687916/361 | H7: 0bbfb15e3ab47bcadc3b391094b14e1fd88870b4206a3f6a7c77dc1a41b98b08 | I7: d1fbeafdea6d73036b8d08ac4ce66c97b77bb31a6046cd0b85a28cc48a6bc3d9 | J7: 86730efcbe55568fc54cd68842afc91c8170e4738162097e6cc0808ef5ec4a2a | K7: 56b053a4e36bed56a15fc0ca3eb47c27253b7fe0558e355da15b5121693e0360
B8: December #1 | C8: 45271 | D8: https://t.me/c/1522687916/369 | H8: 33876bb46b2b2828e6bfa292fdf5b6ceebd44089f1c27e3a83fbbed7c8b0cd84 | I8: 43066fb014884d80d542e7b518d5441feb1c2aaa6db3628eb3f4dbd5967f854c | J8: 7932529d2af6e4d7c8699211b5f1d74f04556e73d26f7202eb1d7d0b1f7cedb8 | K8: 426ded707d991345c28170c882846d1a310b70fa220aa3cb78ecf1ade9717e9b
A9: 2024 | B9: January #1 | C9: 45306 | D9: https://t.me/c/1522687916/372 | E9: 6dd26ae1a945f870238acca678622c5554d59a0cb4ae5c159e0679bfcd6ede19 | H9: e51833b9d69e71a1964e3fb05fa9d9e811da892d1be36952608daed1a510be1a | I9: fe18dd7c36eceb66900c153b0536bd3b84389f3192c230c3a9e9c0367e90566b | J9: 13a43dd6b384aaf3352f9368ae0c53641569e6402af9ec05808511996c2e188c | K9: b603453bb85d24458562cfd5af49bee7bec650a26c8339f2c33a5bef19acc6f5
B10: January #2 | C10: 45321 | D10: https://t.me/c/1522687916/379 | H10: c96316cda6b12dede86e5493a4e76724bb70899b91fd769a57d7e7689f8686a9 | I10: 951c9127773d87161479e45dcba1d766a359d6f1008ee958cd6afcf7a1149488 | J10: 487492339725716661c5ba1db552a2ea2493759988253b2edc51624fb28e21df | K10: a11ba64cfcf1f36c36a4ade98651cc3ee3d706d21cd8c3adc50db8c3b5f4943b
B11: February #1 | C11: 45334 | D11: https://t.me/c/1522687916/391 | H11: 9d8378bf3ea12a0b4da57cb20c6323f5263b2d57fea4c02d77c5926fa1f57b46 | I11: 3fb1f992e5414e461b8cd8503700e2a9400c9d74b700577a253931e0b5fbe76d | J11: fdff1386e5a2b340e170b91d49ae77a63a47569e3ae017ba8b54ef37dda4c1ca | K11: 05a56689a4f97951a5a72ec3d7f900f8732e37395b8495a31ba47da5f1d3bc69
B12: February #2 | C12: 45349 | D12: https://t.me/c/1522687916/401 | I12: d2d3dd643796deb63c411c6ac46c62bc42850e4a15bc1ad79968e3220ef979cb | J12: b4a70d65bc28f5ed796f3b5d95aa380ab292dc499cb2a99e0127596c5cd29e14 | K12: 3ec653057c545f16e259ce6a3da4531a83fb5c3b4d06633d6740dee37e5ac4e4
B13: March #1 | C13: 45362 | D13: https://t.me/c/1522687916/413 | I13: c3f4f08770c5525c131d44cef26d0d1423b638aeb4a2b41419945161eae7e623 | K13: b6e1c9a5630feb934c16a06dd25ed1dab1ff3dfa45aac90877c10b45ce39bbe7
B14: March #2 | C14: 45366 | D14: https://t.me/c/1522687916/418 | L14: 1e1c32004b864c7cbb495e8ff884a04eda4a6106675a60b6760c2b198da8deb2 97fc940a82a5cd3453f3435d4d0835e69059f33fe0683907e66b72e326a41ba0
B15: March #3 | C15: 45379 | D15: https://t.me/c/1522687916/424 | H15: a16bc4ccc60875f2edd7a289fe8880ac533f203f5d43ad299c8651eeae4b8692 | I15: 6ce75cbf4a215d3bdc1ebd64ff270cacd64c14589719dba3cca072e8eebdddc5 | J15: 7410c6d41e25a010a9b171b635324eb7a89d228882e6d14f011b60aadf3fca71 | K15: 7c897c8d903fc58d3a24b69d15382f4a428d84eb63d649f0ac6016056761c749 | L15: fcc0d894622818d167429c3af4ffdeaab503a79f0a1861dfb7422005820fc856
B16: April #1 | C16: 45390 | D16: https://t.me/c/1522687916/426 | H16: 78b789cf70a5bb8a81a9745d0d1e5db777229d20bd0d462aca9c982acc2d6721 | I16: 051a29a01b0164ef608a3171d43826d6ee2e0fe3801070b4c3442c8364afd42d | J16: 42ed9db67ae909f72b1ad7b3cc16ae0dc68147e6b25211f0238d0f1e5f767e8d | K16: f39b56ead8a684679aa11f8cd1de1a62bd7b0e465b3cade02768aaf8ed552d6e | L16: 42a09d20ef9d938d7cf162e85e3e1a11ca2a1ea8aa2167c85c68d43d5aa47b91
B17: April #2 | C17: 45405 | D17: https://t.me/c/1522687916/437 | J17: 6c07ff12f909f1849847b2b2235a1bd4874d4f0e7bc05214afc5f81bf6885b3b | K17: d28ff3e1c561e2c1e3aa4270635e602d1aa1fcf3ef076399a2f5cd7bd3950341 | L17: 04aef83fac4042d16fb1b7a81bbde4d592220df7a042d94492d3730f30796e18
B18: May #1 | C18: 45428 | D18: https://t.me/c/1522687916/450 | H18: 15f4995c4ff3ab6dad99864b16b4369b54f062d043b32504837a88ec9c956bd4 | I18: adb1ad59ea19285edcfecb17f9bbd24c1538323326a6dcc3366902191c09ad3f | J18: 1af5bfd692efb233d86a250b41adb4b7de691e447ef26fafe9cfe5f036446b33 | K18: 2ea020481b5f263ae52c68c44566cc8783884f4b112a7771c9108a3aa136f5b8 | L18: c1d89a671b58fbba0740cb8aae907afd95fd6cfbd7e460c5ae1198236869b1ce
B19: May #2 | C19: N/A | D19: N/A
B20: June #1 | C20: 45454 | D20: https://t.me/c/1522687916/461 | H20: 330cbb7f86606e473374d497745b06a91a9a5b1d5a2fe3d1540aab579b0c1c3a | I20: 0babda03734309a3c473630b24fe5d44487f1c50d191130c122c766f29cd8731 | J20: 20be8edce6b70d77523a61062be0f144985a0141e88e2f1b280d4dd1ce26fa13 | K20: b482f165a2bc82a88618211312f43e6169017407124cb02b094f0092b395eb71 | L20: 8b5f9033c0b3bcd6c8deeabc4ce63d4a34df37f5220af2fb76aeda872d814913
B21: June #2 | C21: N/A | D21: N/A
B22: July #1 | C22: 45481 | D22: https://t.me/c/1522687916/468 | I22: d3a5623c5484815318fe8cef4708a0f81ebde2a1f02745e810d83f32eb72ae6a | J22: f5a4fb9c28d949273fd4ecf5cd0728254346d9445cb0cbacb3e67324d2ea8087 | K22: da974b0a50e60b57fc150dbbbe0d52e04141c8dda62ecc03ab9de3046d9937c4 | L22: b9952d05fac2836ec79bbc5df18db0e7fdfc578eec5644bac204885a695f3c89
B23: July #2 | C23: 45506 | D23: https://t.me/c/1522687916/474 | F23: 94248a1dca33cb8be7aaae6dbf6e0e734f798294c242d252079b2f61daedf6da | I23: ee6fbaa9e8f654e6768d3075b12a6fd7deeaa125eb49fc4278ac31fc06327938 | J23: 8101364984cabf655e8c9aaeb17d4ad3c0586feba7032859ebaca99fa502a70f | K23: c33d499ca68d73364fea50c0cffeb81a044e9ec8d65e6c71955bb422b5e1b67a | L23: bc9caf79e5d29a37671c061c645470acb33990d6b88727e7de162faf6856f9e0
B24: August #1 | C24: 45533 | D24: https://t.me/c/1522687916/482 | H24: 4cdee8c6a71c2c444aaf0aa1b87b8a589801817b2e3d70a82fc227e48fde8449 | J24: 453bd7afe0aee80f23eaae103a161d213f169052289403114e612b15ee9b80a3 | K24: 699d2005877e0f1b06ebcba7e9a1be4db8d1cb7409eda778b464dd86535980f6 | L24: 556d317bfe8738fa9a833ca9746abf4836e6c1e1a4bf7b883c57ea91908cda05
B25: August #2 | C25: N/A | D25: N/A
B26: September #1 | C26: 45547 | D26: https://t.me/c/1522687916/486 | K26: d62642e769d842b9e5c9b73281120d8b52018928515e4e16f2f24c6a0abd206f | L26: 1a0c19ba1ba87852b4e53ad9ac7d921fcf3f067bd893b8a54e31211c76dd4167 | M26: 29edc2cd98460685c0e309595d2c8f7090bf925aead573555abb12458f5c957d
B27: September #2 | C27: 45566 | D27: https://t.me/c/1522687916/494 | I27: 4937b08eabc2db8bd612ab12edb94eb5e2fa0f9b1bc3656517a5510467223532 | K27: 3f81f78309fd4caa5d2b23b358188d620448a3709ec97628f58035186471701b | L27: 8887b6018a612fa67ce62f75911538d814bb45ede9f92e570046e00c8cf85621 | M27: 2617b25592527fd1024a0ea15fb994c907ddc2de840efe830d932c9f5568f345
B28: October #1 | C28: 45581 | D28: https://t.me/c/1522687916/497 | J28: c52d6ef803929e06c94cd6d8e7ff7e1f7d4975cfb6a9084fe9cb80f9cb958199 | K28: 8a23780e6ec5d5404bbbd1b8b89bcb8eeb38042932d3574ba66a16269ee78ed6 | L28: d9b7a51e5e08a7bd7622f2bf685f70705f9b3516cdd1d896b2ce3a4d75a71721 | M28: d78915b139dae29bc025b86c0b6b615bdd2e99ad124d00cd360ab736c11a1c71
B29: October #2 | C29: 45596 | D29: https://t.me/c/1522687916/500 | K29: a2747639d73edbf3df226479676ab87672df6272df885c557b20ddfa06b680c0 | L29: 4be342044345e63f2c71304ff6a91975d6a8f1990cc49abab4839e0ab70d211d | M29: d9c658fe4d2be8710009dabbf1746535a640c0e8aa0e0c28464bc2284cd35c71
B30: November #1 | C30: 45615 | D30: https://t.me/c/1522687916/507 | H30: 786db177c39d87da733d4bea8d959c958ed1c66ff6824586bffe33fd3045b79c | I30: e07d1e2ef8c0fd09023bad8fd945399c157090ea6aff8fc8c2aaf72ba220093a | K30: 2f5a6cacc8d6ec1da974a49d7e40e6a3932b1c80fd03f167a67929f9954ac1b6 | L30: 18bcd23c45fd54e393aaa5f48b20979a61ad4abb39005843c6d50b8fb484fae3 | M30: 12d9e020db3cedc21aa936aa9d7642d736e91531110b33a639c927fd9c0dea0f
B31: November #2 | C31: 45628 | D31: https://t.me/c/1522687916/509 | K31: 4d77e3c52113be9a0b4bf2693820d22e556723f1d1c1c44f0015cf0dd4263542 | L31: 568063bded1f5722b84494c9865cf511907f2789fce451ff320eaff0159e839c | M31: 3dfbcb687defa153fd33fa21fee78e23e002ff2a43700ec4ac7f7ab326532fc5
B32: December #1 | C32: 45642 | D32: https://t.me/c/1522687916/514 | I32: bec6334451e50dbe85a6fe353d76120c320cb78436fbb23a98189e3c55949962 | J32: fe8020cc8e9ed3c23761548dd6a854c66ef1a93d6abd1e4c5a40e8c62ae78552 | K32: 6ce51a855da8feec8fc36b4b7c3472a7c7d9033352070c67772fc8ec3f44809e | L32: d4fe884fadd6865da11ec19b340ea44fcfe691b4fc7735e94307da82be13eab2 | M32: 734eb7388630cbaf8593827ca7f5d2ad309e701a26b0eb4d5524bc0908711877
A33: 2025 | B33: January #1 | C33: 45673 | D33: https://t.me/c/1522687916/520 | H33: d6fbfce98a189e855a078e57df7cf65af25dff72158608de3578af6070a10a9f | I33: be259e338d0c9d95b2e5df204c2e6696e37a32ff1078ba8d61ab3006b7faeeba | J33: 724bbed34482844a276882163f2f379bda67d42b1eee3b0e5b469e72d7cb277e | K33: 8370b0f959891b944c5c8fbba7689c468a8f05966316b2b445b524372a789169 | L33: 1050398f7ccc301e85979b09541010fcf513deb2dc7ef26dccea4167ce3eecc2 | M33: 23df1e6afe6ef7737c4f443c7a94f1c95fabb3fb0878e43a83f256b5d726d464
B34: January #2 | C34: 45687 | D34: https://t.me/c/1522687916/527 | J34: cc8331e4da46e75e91847249c860fdaf243f1bfb574f28ab651f14271271876e | K34: cd60a426e4428342591479d94447ecb1327244bff066e791e1467bd5b94f0787 | L34: dd9c0d029e37851e08f03fe24036784985415d233586f8c85275b94fe6411888 | M34: 7dc5e2b5dbfbd9e7b293bdc0e6881e15ee79c7989ec7c8f0f06074c72ae6f038 | N34: 85a3171d405634aa337c972554c4d557fc6f0ced59255605944252108a1de884
B35: February #1 | C35: 45701 | D35: https://t.me/c/1522687916/531 | J35: 42559dffa8d36341230375bb34083b3d4e96d39e1ec752c08f6909ef9d56fd5a | K35: 31101b4710161df50b6b6d69ce9dd0196f3e4b6cc5941163ae248a4c1ea10fd1 | L35: f748692055487689e4afe3fe2c96797357d7a6afca99c54af033780aac87117d | M35: a208179fae7056ba8e768ab2f20f8b79857951a5675a2077de7a8648132783bf | N35: 9994469fa6f3d5adddb46d2b2ab2ef77c77395a01f8b487005bbe2664427d5ea
B36: February #2 | C36: 45713 | D36: https://t.me/c/1522687916/533 | I36: 74e6de01a1dcb03b9e4da5787216c37b811d737957a3f0eae9dfdfbd5c3cbc95 | J36: 5a2a570748400d5094f9ac969848e805dcb02526eaffb6a6420bd37b1c0a02c7 | K36: 7d1780e84f6f2f01035bd96631fc3a34608c4f8d0c668aa51116038220761a83 | L36: 138ecc3d485cb4167000a557d1871dc85a58cf4cfe11b7ff96ef5e9db528d2ec | M36: 26ca288a0865454caf3f5af6c92c98ad627be27189380fa0005e27ed5079ba9f | N36: d94bb5660fc55dfe2e08eadf2ce69fc817ec3a8f825dc07fe02c6c3a128fd1a2
B37: March #1 | C37: 45729 | D37: https://t.me/c/1522687916/535 | I37: 2218df78edf664dc74dd2dfb61448d27d3b1cb92530990eafc3f2d7095994b20 | J37: 6383a4cb036f379aae567702d55a45866f658a45b56681e24aef6618de3e13cb | K37: 19654d16c2a1ed8975b729796c7d6fc9bb9cb4a6846a74196981946194c921c9 | L37: 9f9d44080c9d98611b2909eecf7c99e784dd8d24dc983fd1e18c1de108500f96 | M37: 052cd36b6fe2e4c050eb5b7c9c7d2ebcacb05380df3146ea8eafc8ed1c4a806f | N37: 1ac231fb7090528861eb0e7373a2581373c0a8b41fd1cdd217f3a6decb5ce3f2
B38: March #2 | C38: 45741 | D38: https://t.me/c/1522687916/541 | K38: f2e8c6c0da38b7ae26d5c3be5e4be733abfeea19c8e669a4491d4eea54e7f877 | L38: e0fc69a9397bbdbe989e8be3d40a84db1a07d4e659e4de5b11ded3b691d636c7 | M38: 443f75f83355a5adb69c1cb8dfe80350a9eeaf6999fb32d217ddf1ce8cf7d7d3 | N38: 4cf8862e942b50a18b0031ce8bba3c12f9b5dfbf00986f20db28b27363bfe5e3
B39: April #1 | C39: 45762 | D39: https://t.me/c/1522687916/547 | J39: c9dee487b0633358e02ab3e4dd1de07c8d93b7189191d99cfd2451435e8730b6 | K39: 8832fbc697338456c04635a916d7881cab71cf1b5a743b665ab9489f389d08a8 | L39: 252e81b010c1186beb45f1b40c7204cdfb12a7c1240493beaefc78d0fa2897a2 | M39: f475467c9b2f0eb4833dac51a3a5f43fdd7ae92c21cc19cda9b642e06a2372d1 | N39: da23226af171165a5b137bb055a4e4f51e95b08eeb2f38cba93f82a621cd0ec9
B40: April #2 | C40: 45776 | D40: https://t.me/c/1522687916/553 | I40: 19a6dd38ba68d20331e54f5927d35d2299c5395f3d11e6f1e9116389dab0d1cf | J40: dc0e180d53218316a86e5237dc3efe3226a3d0e97de8bf2ae07cadbfa6a23e09 | K40: 5d6c13043377e2c6cb967a52a1478f855f654e43cafecc0f7a3258b613edcda2 | L40: 14017cf2acfe895be67ec152fc49ec02778e89ec6962e8465a124e9dd8b835b8 | M40: 3fc5734cca297259dde45830990ba20b024a1042d051ff7ae236e90f51b40f32 | N40: 6c4821787c89e4073bda62ebbf486137de73ea5c6390895e939a065f5d82b1e3
...

Sheet Fund14 Reporting
A1: THIS DOCUMENT WILL BE DEPRECATED SOON If you need support please submit a ticket via zendesk.
C4: FUND14 | E4: Funding (₳)
A5: # | B5: ID | C5: Project Name | D5: Project Status | E5: Requested | F5: Distributed to date | G5: Remaining | H5: Primary Proposer - Guarantor | I5: Challenge
E6: =SUM(E9:E139) -> 18591246 | F6: =SUM(F9:F139) -> 4230962.4 | G6: =SUM(G9:G139) -> 14360284
C8: =Counta(C9:C139) -> 131
A9: 1 | B9: 1400001 | C9: [Aladin]: Building a Freelancer Community for Cardano | D9: PENDING | E9: 56380 | F9: 11276 | G9: =E9-F9 -> 45104 | H9: Thanh Nguyen | I9: Cardano Open: Ecosystem
A10: 2 | B10: 1400002 | C10: [C2VN]: Hydra on Cardano – Complete Step-by-Step DApp Guide | D10: PENDING | E10: 30120 | F10: 12960 | G10: =E10-F10 -> 17160 | H10: Khanh Duy Nguyen | I10: Cardano Open: Ecosystem
A11: 3 | B11: 1400003 | C11: A Token-Incentivized Mental Health Ecosystem Using DID | D11: PENDING | E11: 100000 | F11: 16000 | G11: =E11-F11 -> 84000 | H11: Mineko Enomoto | I11: Cardano Use Cases: Concept
A12: 4 | B12: 1400004 | C12: Activating IPDC Blockchain through Real Broadcasting Waves | D12: PENDING | E12: 100000 | F12: 24000 | G12: =E12-F12 -> 76000 | H12: JUN HAMADA | I12: Cardano Use Cases: Concept
A13: 5 | B13: 1400005 | C13: AIRA : Hydra Loyalty & Crypto for Regional Revitalization | D13: PENDING | E13: 698000 | F13: 0 | G13: =E13-F13 -> 698000 | H13: Shigeki Tabira : AIRA Inc, CEO | I13: Cardano Use Cases: Partners & Products
A14: 6 | B14: 1400006 | C14: Amplify Cardano: Community-Led Events by Rare Network | D14: PENDING | E14: 50000 | F14: 12000 | G14: =E14-F14 -> 38000 | H14: Wes Parkinson | I14: Cardano Open: Ecosystem
A15: 7 | B15: 1400007 | C15: Amplify Cardano: Community-Led Marketing by Rare Network | D15: PENDING | E15: 50000 | F15: 12000 | G15: =E15-F15 -> 38000 | H15: Wes Parkinson | I15: Cardano Open: Ecosystem
A16: 8 | B16: 1400008 | C16: An all-in-one platform for the Korean Cardano community | D16: PENDING | E16: 30000 | F16: 16200 | G16: =E16-F16 -> 13800 | H16: KTOP SPO | I16: Cardano Open: Ecosystem
A17: 9 | B17: 1400009 | C17: Anastasia Labs - Smart Contract Design Patterns Conway+ | D17: PENDING | E17: 100000 | F17: 0 | G17: =E17-F17 -> 100000 | H17: Philip DiSarro | I17: Cardano Open: Developers
A18: 10 | B18: 1400010 | C18: Anti-Front-Running ZKPerps on Cardano w/MidnightZK | D18: PENDING | E18: 74000 | F18: 16000 | G18: =E18-F18 -> 58000 | H18: Sricharan Ganta | I18: Cardano Use Cases: Concept
A19: 11 | B19: 1400011 | C19: Anvil - Semi-Custodial Wallet: Enterprise ready Wallet SDK | D19: PENDING | E19: 60000 | F19: 27600 | G19: =E19-F19 -> 32400 | H19: Zachary Soesbee | I19: Cardano Use Cases: Concept
A20: 12 | B20: 1400012 | C20: Bifrost: Bitcoin-Cardano bridge secured by Cardano SPOs | D20: PENDING | E20: 739000 | F20: 0 | G20: =E20-F20 -> 739000 | H20: Matteo Coppola (FluidTokens) | I20: Cardano Use Cases: Partners & Products
... A139: 131 | B139: 1400131 | C139: ZK-Stables: USDC/USDT Non Custodial Bridge | D139: PENDING | E139: 85000 | F139: 59500 | G139: =E139-F139 -> 25500 | H139: Dextr Labs | I139: Cardano Open: Developers

Sheet Fund13 Reporting
A1: THIS DOCUMENT WILL BE DEPRECATED SOON If you need support please submit a ticket via zendesk.
C4: FUND13 | E4: Funding (₳)
A5: # | B5: ID | C5: Project Name | D5: Project Status | E5: Requested | F5: Distributed to date | G5: Remaining | H5: Primary Proposer - Guarantor | I5: Challenge
E6: =SUM(E9:E207) -> 46476623 | F6: =SUM(F9:F207) -> 31425560 | G6: =SUM(G9:G207) -> 15051063
C8: =Counta(C9:C207) -> 199
A9: 1 | B9: 1300001 | C9: “Cardano Unleashed: Hybrid Events to Inspire Innovation” | D9: PENDING | E9: 50000 | F9: 27000 | G9: =E9-F9 -> 23000 | I9: Cardano Open: Ecosystem
A10: 2 | B10: 1300002 | C10: "Together Learning Haskell/Plutus in native language" Club (Phase 2) | D10: COMPLETED | E10: 35500 | F10: 35500 | G10: =E10-F10 -> 0 | I10: Cardano Open: Ecosystem
A11: 3 | B11: 1300003 | C11: [BBO] Virtual Assistant GovernCardanoBot = AI + Telegram - A tool to help you better understand Cardano Governance | D11: COMPLETED | E11: 66250 | F11: 66250 | G11: =E11-F11 -> 0 | I11: Cardano Open: Developers
A12: 4 | B12: 1300004 | C12: [BUTC] Fueling Growth: Cardano Hackathons to Inspire Startup Success | D12: COMPLETED | E12: 68000 | F12: 68000 | G12: =E12-F12 -> 0 | I12: Cardano Open: Ecosystem
A13: 5 | B13: 1300005 | C13: [C2VN]: Promoting education through the development of Blockchain lecturer teams at universities in Vietnam (Phase 2: Advanced course on on-chain and off-chain programming on the Cardano Blockchain) | D13: COMPLETED | E13: 67900 | F13: 67900 | G13: =E13-F13 -> 0 | I13: Cardano Open: Ecosystem
A14: 6 | B14: 1300006 | C14: [DLC] Cardano Ecosystem Growth - Marketing DeFi Products | D14: COMPLETED | E14: 100000 | F14: 100000 | G14: =E14-F14 -> 0 | I14: Cardano Open: Ecosystem
A15: 7 | B15: 1300007 | C15: [DLC] Cardano Ecosystem Growth - Short Form Video Marketing | D15: COMPLETED | E15: 100000 | F15: 100000 | G15: =E15-F15 -> 0 | I15: Cardano Open: Ecosystem
A16: 8 | B16: 1300008 | C16: [HTLABS] 5 Project templates combining blockchain and internet of things | D16: PENDING | E16: 35857 | F16: 18000.01 | G16: =E16-F16 -> 17856.99 | I16: Cardano Open: Developers
A17: 9 | B17: 1300009 | C17: [LANTR] Scalus: Multiplatform Tx Builder – same code for front&backend | D17: COMPLETED | E17: 100000 | F17: 100000 | G17: =E17-F17 -> 0 | I17: Cardano Open: Developers
A18: 10 | B18: 1300010 | C18: [PKL] Cardano Governance Explorer Visualized with Graphs | D18: COMPLETED | E18: 120000 | F18: 120000 | G18: =E18-F18 -> 0 | I18: Cardano Use Cases: Concept
A19: 11 | B19: 1300011 | C19: [Tempo] Multi-party alliance | D19: PENDING | E19: 135000 | F19: 45000 | G19: =E19-F19 -> 90000 | I19: Cardano Use Cases: Concept
A20: 12 | B20: 1300012 | C20: 🇻🇳 Cardano App Development Course: A Step-by-Step Guide for Beginners - From basic Web development to use Cardano Libraries and interacting with Smart Contracts | D20: PENDING | E20: 34857 | F20: 27000 | G20: =E20-F20 -> 7857 | I20: Cardano Open: Ecosystem
... A207: 199 | B207: 1300199 | C207: zkFold x Asterizm - Interoperability Solution | D207: PENDING | E207: 500000 | F207: 420000 | G207: =E207-F207 -> 80000 | I207: Cardano Use Cases: Product

Sheet Fund12 Reporting
A1: THIS DOCUMENT WILL BE DEPRECATED SOON If you need support please submit a ticket via zendesk.
C4: FUND12 | E4: Funding (₳)
A5: # | B5: ID | C5: Project Name | D5: Project Status | E5: Requested | F5: Distributed to date | G5: Remaining | H5: Primary Proposer - Guarantor | I5: Challenge
E6: =SUM(E9:E266) -> 46484802 | F6: =SUM(F9:F266) -> 36912782 | G6: =SUM(G9:G266) -> 9572019.7
C8: =Counta(C9:C266) -> 258 | D8: =COUNTIF(D9:D266,"=COMPLETED") -> 163
A9: 1 | B9: 1200001 | C9: [5PC] Cardano Journey - Cardano Education Podcast Series for the Vietnamese Community | D9: COMPLETED | E9: 17352 | F9: 17352 | G9: =E9-F9 -> 0 | H9: 5 Minutes Crypto | I9: Cardano Open: Ecosystem
A10: 2 | B10: 1200002 | C10: [C2VN]: Cardano blockchain courseware in Universities | D10: COMPLETED | E10: 92000 | F10: 92000 | G10: =E10-F10 -> 0 | H10: cardano2vn | I10: Cardano Open: Ecosystem
A11: 3 | B11: 1200003 | C11: [C2VN]: Developing the Blockchain Lecturer Team at Universities in Vietnam | D11: COMPLETED | E11: 41250 | F11: 41250 | G11: =E11-F11 -> 0 | H11: nvhieu | I11: Cardano Open: Ecosystem
A12: 4 | B12: 1200004 | C12: [CaFi] Cardano news - Vietnamese version | D12: COMPLETED | E12: 17995 | F12: 17995 | G12: =E12-F12 -> 0 | H12: Duc Nguyen | I12: Cardano Open: Ecosystem
A13: 5 | B13: 1200005 | C13: [CaFi] Peer-Reviewed Technical Research Paper Library in Vietnamese version | D13: COMPLETED | E13: 18873 | F13: 18873 | G13: =E13-F13 -> 0 | H13: Tu Nguyen | I13: Cardano Open: Ecosystem
A14: 6 | B14: 1200006 | C14: [CASIA] Cardano Asia TikTok Channel (expand Korean, maintain Japanese/Vietnamese/English) + NEW Youtube Channel | D14: COMPLETED | E14: 79028 | F14: 79028 | G14: =E14-F14 -> 0 | H14: Cardano_Asia Team | I14: Cardano Open: Ecosystem
A15: 7 | B15: 1200007 | C15: [FIMI] Blockchain course for Vietnamese | D15: COMPLETED | E15: 74900 | F15: 74900 | G15: =E15-F15 -> 0 | H15: Fimi | I15: Cardano Open: Ecosystem
A16: 8 | B16: 1200008 | C16: [FIMI] Podcast Cardano on Telegram for Vietnamese | D16: COMPLETED | E16: 57150 | F16: 57150 | G16: =E16-F16 -> 0 | H16: Fimi | I16: Cardano Open: Ecosystem
A17: 9 | B17: 1200009 | C17: [nftcdn.io] Open Source JavaScript NFT Media Viewer/Player (music, video, 3D, etc.) | D17: COMPLETED | E17: 195349 | F17: 195349 | G17: =E17-F17 -> 0 | H17: Smaug | I17: Cardano Open: Developers
A18: 10 | B18: 1200010 | C18: Academic Research at UBA, one of the most prestigious Universities in LATAM, with focus on Decentralized Governance Research. | D18: COMPLETED | E18: 96000 | F18: 96000 | G18: =E18-F18 -> 0 | H18: LATAM Cardano Community | I18: Cardano Open: Ecosystem
A19: 11 | B19: 1200011 | C19: Accelerate Mass Adoption: Open Source Atala Wallet SDK with No Seed Phrase Vulnerability and a No-Code Self-Sovereign Identity Platform | D19: COMPLETED | E19: 489091 | F19: 489091 | G19: =E19-F19 -> 0 | H19: Socious Team | I19: Cardano Use Cases: Product
A20: 12 | B20: 1200012 | C20: ADA Cashback from Top Retailers, for Cardano Wallets | D20: COMPLETED | E20: 100000 | F20: 100000 | G20: =E20-F20 -> 0 | H20: Ethan Hanoch | I20: Cardano Use Cases: Concept
... A266: 258 | B266: 1200258 | C266: µgraph: Instant, Untraceable Payments in Cardano | D266: PENDING | E266: 300000 | F266: 192000 | G266: =E266-F266 -> 108000 | H266: Cainã Costa | I266: Cardano Use Cases: MVP

Sheet Fund11 Reporting
A1: THIS DOCUMENT WILL BE DEPRECATED SOON If you need support please submit a ticket via zendesk.
C4: FUND11 | E4: Funding (₳)
A5: # | B5: ID | C5: Project Name | D5: Project Status | E5: Requested | F5: Distributed to date | G5: Remaining | H5: Primary Proposer - Guarantor | I5: Challenge
E6: =SUM(E9:E308) -> 46489869 | F6: =SUM(F9:F308) -> 41424810 | G6: =SUM(G9:G308) -> 5065059
C7: Reporting %
C8: =Counta(C9:C308) -> 300
A9: 1 | B9: 1100001 | C9: "Together Learning Haskell/Plutus in native language" Club | D9: COMPLETED | E9: 33000 | F9: 33000 | G9: =E9-F9 -> 0 | H9: Tam Hoang | I9: Cardano Open: Ecosystem
A10: 2 | B10: 1100002 | C10: (Dead-man-switch) Permission based Wallet | D10: PENDING | E10: 100000 | F10: 8000 | G10: =E10-F10 -> 92000 | H10: Sandro Schaier | I10: Cardano Use Cases: Concept
A11: 3 | B11: 1100003 | C11: 10 Marlowe contract templates - the real life use cases | D11: PENDING | E11: 99040 | F11: 77040 | G11: =E11-F11 -> 22000 | H11: Jimmy Lee | I11: Cardano Open: Developers
A12: 4 | B12: 1100004 | C12: 45B - Marlowe workshops for Business professionals | D12: PENDING | E12: 49500 | F12: 19602 | G12: =E12-F12 -> 29898 | H12: 45B - Cardano Enablement | I12: Cardano Open: Ecosystem
A13: 5 | B13: 1100005 | C13: [5PC] Cardano Education Video on TikTok for the Vietnamese Community | D13: COMPLETED | E13: 15392 | F13: 15392 | G13: =E13-F13 -> 0 | H13: 5 Minutes Crypto | I13: Cardano Open: Ecosystem
A14: 6 | B14: 1100006 | C14: [C2VN] Accelerate Atala PRISM learning and adoption in Universities | D14: COMPLETED | E14: 148225 | F14: 148225 | G14: =E14-F14 -> 0 | H14: cardano2vn | I14: Cardano Open: Ecosystem
A15: 7 | B15: 1100007 | C15: [C2VN]: Cardano developer club in Universities | D15: COMPLETED | E15: 118361 | F15: 118361 | G15: =E15-F15 -> 0 | H15: cardano2vn | I15: Cardano Open: Ecosystem
A16: 8 | B16: 1100008 | C16: [FIMI] cardano.vn - Cardano information portal for Vietnamese people | D16: COMPLETED | E16: 17550 | F16: 17550 | G16: =E16-F16 -> 0 | H16: Fimi | I16: Cardano Open: Ecosystem
A17: 9 | B17: 1100009 | C17: [FIMI] Free Marlowe Course for Vietnamese | D17: COMPLETED | E17: 25000 | F17: 25000 | G17: =E17-F17 -> 0 | H17: Fimi | I17: Cardano Open: Ecosystem
A18: 10 | B18: 1100010 | C18: [FIMI] Plutus Pioneer #4 - Translating video dubbing in Vietnamese | D18: COMPLETED | E18: 20628 | F18: 20628 | G18: =E18-F18 -> 0 | H18: Fimi | I18: Cardano Open: Ecosystem
A19: 11 | B19: 1100011 | C19: Account NFT Smart-contract - Mint Verifiably Unique User Accounts that store data on-chain | D19: COMPLETED | E19: 140000 | F19: 140000 | G19: =E19-F19 -> 0 | H19: Peyton(bigpey) | I19: Cardano Open: Developers
A20: 12 | B20: 1100012 | C20: Accra Resource Center: Igniting African Youth in Cardano & Decentralised Web Innovation. | D20: COMPLETED | E20: 180000 | F20: 180000 | G20: =E20-F20 -> 0 | H20: Afia Owusu | I20: Cardano Open: Ecosystem
... A308: 300 | B308: 1100300 | C308: đź‡»đź‡ł The Complete Aiken Course Cardano: From Zero to Expert! | D308: COMPLETED | E308: 20000 | F308: 20000 | G308: =E308-F308 -> 0 | H308: Blockalpha Innova | I308: Cardano Open: Ecosystem

Sheet Fund10 Reporting
A1: THIS DOCUMENT WILL BE DEPRECATED SOON If you need support please submit a ticket via zendesk.
C4: FUND10 | E4: Funding (₳)
A5: # | B5: ID | C5: Project Name | D5: Project Status | E5: Requested | F5: Distributed to date | G5: Remaining | H5: Primary Proposer - Guarantor | I5: Challenge | J5: Progress Report | K5: Progress Report
E6: =SUM(E9:E200) -> 50857438 | F6: =SUM(F9:F200) -> 44470209 | G6: =SUM(G9:G200) -> 6387229.1 | J6: November '23 | K6: December '23
C7: Reporting % | I7: =Average(J7:K7) -> 0.71465969 | J7: =J8/($C$8 - (COUNTIF(J9:J200, "COMPLETED")+COUNTIF(J9:J200, ""))) -> 0.7434555 | K7: =K8/($C$8 - (COUNTIF(K9:K200, "COMPLETED")+COUNTIF(K9:K200, ""))) -> 0.68586387
C8: =Counta(C9:C200) -> 192 | J8: =COUNTIF(J9:J200, TRUE) -> 142 | K8: =COUNTIF(K9:K200, TRUE) -> 131
A9: 1 | B9: 1000001 | C9: [3] Student-Driven Demonstration of the Use of SSI and the Cardano Blockchain to Capture their Cardano Blockchain Skills | D9: COMPLETED | E9: 17800 | F9: 17800 | G9: =E9-F9 -> 0 | H9: Mark Byers | I9: F10: Startups & Onboarding for Students | J9: TRUE | K9: FALSE
A10: 2 | B10: 1000002 | C10: [Fimi] Cardanotalk for Vietnamese | D10: COMPLETED | E10: 33000 | F10: 33000 | G10: =E10-F10 -> 0 | H10: Fimi | I10: F10: Catalyst Open | J10: FALSE | K10: TRUE
A11: 3 | B11: 1000003 | C11: [Fimi] CatalystTalk for Vietnamese | D11: COMPLETED | E11: 16500 | F11: 16500 | G11: =E11-F11 -> 0 | H11: Do Viet Cuong | I11: F10: Catalyst Open | J11: TRUE | K11: TRUE
A12: 4 | B12: 1000004 | C12: 🇻🇳 Vietnam Cardano Catalyst - NFT Exchange testing and development environment helps young people approach with the Web3.0 platform | D12: COMPLETED | E12: 32000 | F12: 32000 | G12: =E12-F12 -> 0 | H12: Khuat Dinh Thanh | I12: F10: Startups & Onboarding for Students | J12: TRUE | K12: FALSE
A13: 5 | B13: 1000005 | C13: A Zero Knowledge Proof framework for Cardano based on Hydra and ZK-SNARKS | D13: COMPLETED | E13: 75000 | F13: 75000 | G13: =E13-F13 -> 0 | H13: Antonio Hernandez | I13: F10: Development & Infrastructure | J13: TRUE | K13: TRUE
A14: 6 | B14: 1000006 | C14: Adosia Open Governance Model | D14: COMPLETED | E14: 107500 | F14: 107500 | G14: =E14-F14 -> 0 | H14: Adosia Operations | I14: F10: DAOs ❤ Cardano | J14: TRUE | K14: TRUE
A15: 7 | B15: 1000007 | C15: Agora Suite Expansion: NFT Standards and Novel Token Structures Integration | D15: PENDING | E15: 275000 | F15: 219999.98 | G15: =E15-F15 -> 55000.02 | H15: john Valdez | I15: F10: DAOs ❤ Cardano | J15: FALSE | K15: FALSE
A16: 8 | B16: 1000008 | C16: Allow Cardano users to call Sidechain smart contracts directly from their Cardano mainnet wallet | D16: COMPLETED | E16: 448276 | F16: 448276 | G16: =E16-F16 -> 0 | H16: Sebastien Guillemot | I16: F10: Development & Infrastructure | J16: FALSE | K16: FALSE
A17: 9 | B17: 1000009 | C17: Allow using NFTs from Cardano and other ecosystem in onchain games hosted in the Cardano ecosystem | D17: PENDING | E17: 650000 | F17: 420000 | G17: =E17-F17 -> 230000 | H17: Sebastien Guillemot | I17: F10: Development & Infrastructure | J17: TRUE | K17: TRUE
A18: 10 | B18: 1000010 | C18: Anastasia Labs - Open Source Production Grade DApps | D18: COMPLETED | E18: 135500 | F18: 135500 | G18: =E18-F18 -> 0 | H18: philipdisarro | I18: F10: Developer Ecosystem - The Evolution | J18: TRUE | K18: TRUE
A19: 11 | B19: 1000011 | C19: Anastasia Labs - Smart Beacons, Router NFTs | D19: COMPLETED | E19: 150000 | F19: 150000 | G19: =E19-F19 -> 0 | H19: micah Kendall | I19: F10: OSDE: Open Source Dev Ecosystem | J19: TRUE | K19: TRUE
A20: 12 | B20: 1000012 | C20: Anastasia Labs - Streamlining Development: A User-Friendly Smart Contract Library for Plutarch and Aiken Design Patterns & Efficiency | D20: COMPLETED | E20: 250000 | F20: 250000 | G20: =E20-F20 -> 0 | H20: philipdisarro | I20: F10: Development & Infrastructure | J20: TRUE | K20: TRUE
... A42: 34 | B42: 1000034 | C42: Cardano Student Blockchain Ambassador Program | D42: COMPLETED | E42: 25000 | F42: 25000 | G42: =E42-F42 -> 0 | H42: Barbara Ofosu | I42: F10: Startups & Onboarding for Students | J42: TRUE | K42: TRUE
A43: 35 | B43: 1000035 | C43: Cardano Summit 2023 NFT Hoodies - Verifiable Ownership Of Real World Merch | D43: COMPLETED | E43: 50000 | F43: 50000 | G43: =E43-F43 -> 0 | H43: Pritesh Gosai | I43: F10: Catalyst Open | J43: COMPLETED | K43: COMPLETED
A44: 36 | B44: 1000036 | C44: Cardano Tax & Accounting Tool | D44: COMPLETED | E44: 300500 | F44: 300500 | G44: =E44-F44 -> 0 | H44: philipdisarro | I44: F10: Products & Integrations | J44: TRUE | K44: TRUE
A45: 37 | B45: 1000037 | C45: Cardano Woman Indonesia | D45: COMPLETED | E45: 24211 | F45: 24211 | G45: =E45-F45 -> 0 | H45: Fanny Wijaya | I45: F10: Catalyst Open | J45: TRUE | K45: TRUE
A46: 38 | B46: 1000038 | C46: CardanoCodex'23: A Hackathon Aiming to Increase Exposure for Cardano Within a Massive Developer Base | D46: COMPLETED | E46: 35666 | F46: 35666 | G46: =E46-F46 -> 0 | H46: Adnan | I46: F10: Startups & Onboarding for Students | J46: FALSE | K46: FALSE
A47: 39 | B47: 1000039 | C47: Cardanoscan.io Maintenance | D47: COMPLETED | E47: 78000 | F47: 78000 | G47: =E47-F47 -> 0 | H47: Strica | I47: F10: Development & Infrastructure | J47: FALSE | K47: FALSE
A48: 40 | B48: 1000040 | C48: CardanoShield: Protecting Cardano Wallet Users | D48: COMPLETED | E48: 250000 | F48: 250000 | G48: =E48-F48 -> 0 | H48: Shawn Roller | I48: F10: Development & Infrastructure | J48: TRUE | K48: TRUE
A49: 41 | B49: 1000041 | C49: Catalyst Africa Town Hall Operations | D49: COMPLETED | E49: 75000 | F49: 75000 | G49: =E49-F49 -> 0 | H49: Catalyst Africa Town Hall | I49: F10: Catalyst Open | J49: TRUE | K49: TRUE
A50: 42 | B50: 1000042 | C50: Catalyst Africa Town Hall: Bridging the Gap for Continental Expansion | D50: COMPLETED | E50: 75000 | F50: 75000 | G50: =E50-F50 -> 0 | H50: Catalyst Africa Town Hall | I50: F10: Catalyst Open | J50: TRUE | K50: TRUE
A51: 43 | B51: 1000043 | C51: Catalyst Completed Project NFTs | D51: COMPLETED | E51: 49800 | F51: 49800 | G51: =E51-F51 -> 0 | H51: LIDO Nation Foundation | I51: F10: Building on NMKR | J51: TRUE | K51: TRUE
A52: 44 | B52: 1000044 | C52: Catalyst Explorer 2.5: Accessible Catalyst Data & Tools | D52: COMPLETED | E52: 172666 | F52: 172666 | G52: =E52-F52 -> 0 | H52: LIDO Nation Foundation | I52: F10: Products & Integrations | J52: TRUE | K52: TRUE
A53: 45 | B53: 1000045 | C53: Catalyst Explorer dRep module: Directory, Community, Draft Ballots | D53: COMPLETED | E53: 148000 | F53: 148000 | G53: =E53-F53 -> 0 | H53: LIDO Nation Foundation | I53: F10: dRep improvement and onboarding | J53: TRUE | K53: TRUE
A54: 46 | B54: 1000046 | C54: Catalyst Fund Operations by IOG Catalyst Team | D54: COMPLETED | E54: 6420000 | F54: 6420000 | G54: =E54-F54 -> 0 | H54: Catalyst Team | I54: F10: Catalyst Fund Operations | J54: FALSE | K54: FALSE
A55: 47 | B55: 1000047 | C55: Catalyst Outreach 4 The Unreached in Ghana | D55: COMPLETED | E55: 21000 | F55: 21000 | G55: =E55-F55 -> 0 | H55: Emelia Sarfo | I55: F10: Catalyst Open | J55: TRUE | K55: TRUE
... A200: 192 | B200: 1000192 | C200: Xerberus: Risk Ratings for all Fungible Assets on Cardano | D200: PENDING | E200: 400000 | F200: 320000 | G200: =E200-F200 -> 80000 | H200: Xerberus | I200: F10: Products & Integrations | J200: TRUE | K200: FALSE

Sheet Fund9 Reporting
A1: THIS DOCUMENT WILL BE DEPRECATED SOON If you need support please submit a ticket via zendesk.
C4: FUND9 | E4: Funding ($)
A5: # | B5: ID | C5: Project Name | D5: Project Status | E5: Requested | F5: Distributed to date | G5: Remaining | H5: Primary Proposer - Guarantor | I5: Challenge | J5: Progress Report | K5: Progress Report | L5: Progress Report | M5: Progress Report | N5: Progress Report | O5: Progress Report | P5: Progress Report | Q5: Progress Report | R5: Progress Report | S5: Progress Report | T5: Progress Report | U5: Progress Report | V5: Progress Report | W5: Progress Report
E6: =SUM(E9:E224) -> 12799696 | F6: =SUM(F9:F224) -> 12040510 | G6: =SUM(G9:G224) -> 759186.21 | J6: November '22 | K6: December '22 | L6: January '23 | M6: February '23 | N6: March '23 | O6: April '23 | P6: May '23 | Q6: June '23 | R6: July '23 | S6: August '23 | T6: September '23 | U6: October '23 | V6: November '23 | W6: December '23
C7: Reporting % | I7: =Average(J7:L7) -> 0.62291953 | J7: =J8/($C$8 - (COUNTIF(J9:J224, "COMPLETED")+COUNTIF(J9:J224, ""))) -> 0.72769953 | K7: =K8/($C$8 - (COUNTIF(K9:K224, "COMPLETED")+COUNTIF(K9:K224, ""))) -> 0.53301887 | L7: =L8/($C$8 - (COUNTIF(L9:L224, "COMPLETED")+COUNTIF(L9:L224, ""))) -> 0.6080402 | M7: =M8/($C$8 - (COUNTIF(M9:M224, "COMPLETED")+COUNTIF(M9:M224, ""))) -> 0.63372093 | N7: =N8/($C$8 - (COUNTIF(N9:N224, "COMPLETED")+COUNTIF(N9:N224, ""))) -> 0.57058824 | O7: =O8/($C$8 - (COUNTIF(O9:O224, "COMPLETED")+COUNTIF(O9:O224, ""))) -> 0.41059603 | P7: =P8/($C$8 - (COUNTIF(P9:P224, "COMPLETED")+COUNTIF(P9:P224, ""))) -> 0.26206897 | Q7: =Q8/($C$8 - (COUNTIF(Q9:Q224, "COMPLETED")+COUNTIF(Q9:Q224, ""))) -> 0.25735294 | ... W7: =W8/($C$8 - (COUNTIF(W9:W224, "COMPLETED")+COUNTIF(W9:W224, ""))) -> 0.0625
C8: =Counta(C9:C224) -> 216 | J8: =COUNTIF(J9:J224, TRUE) -> 155 | K8: =COUNTIF(K9:K224, TRUE) -> 113 | L8: =COUNTIF(L9:L224, TRUE) -> 121 | M8: =COUNTIF(M9:M224, TRUE) -> 109 | N8: =COUNTIF(N9:N224, TRUE) -> 97 | O8: =COUNTIF(O9:O224, TRUE) -> 62 | P8: =COUNTIF(P9:P224, TRUE) -> 38 | Q8: =COUNTIF(Q9:Q224, TRUE) -> 35 | ... W8: =COUNTIF(W9:W224, TRUE) -> 5
A9: 1 | B9: 900001 | C9: 500+ â‚łCommunity Sent to Conferences | D9: DID NOT FINISH | E9: 420000 | F9: 210000 | G9: =E9-F9 -> 210000 | H9: Ninh Tran | I9: F9: Dapps, Products & Integrations | J9: TRUE | K9: FALSE | L9: TRUE | M9: TRUE | N9: FALSE | O9: FALSE | P9: FALSE | Q9: FALSE | R9: FALSE | S9: FALSE | T9: FALSE | U9: FALSE | V9: FALSE | W9: FALSE
A10: 2 | B10: 900002 | C10: A standard for token verification | D10: COMPLETED | E10: 22000 | F10: 22000 | G10: =E10-F10 -> 0 | H10: MuesliSwap Team | I10: F9: Dapps, Products & Integrations | J10: FALSE | K10: FALSE | L10: TRUE | M10: TRUE | N10: TRUE | O10: FALSE | P10: FALSE | Q10: FALSE | R10: FALSE | S10: FALSE | T10: FALSE | U10: COMPLETED | V10: COMPLETED | W10: COMPLETED
A11: 3 | B11: 900003 | C11: Accelerator batch #3 | D11: DID NOT FINISH | E11: 120000 | F11: 10000 | G11: =E11-F11 -> 110000 | H11: Sebastien Guillemot | I11: F9: The Great Migration (from Ethereum) | J11: FALSE | K11: FALSE | L11: TRUE | M11: FALSE | N11: FALSE | O11: FALSE | P11: FALSE | Q11: FALSE | R11: FALSE | S11: FALSE | T11: FALSE | U11: FALSE | V11: FALSE | W11: FALSE
A12: 4 | B12: 900004 | C12: Accounting Reporting France | D12: COMPLETED | E12: 11200 | F12: 11200 | G12: =E12-F12 -> 0 | H12: Yoram | I12: F9: Legal & Financial Implementations | J12: TRUE | K12: TRUE | L12: TRUE | M12: TRUE | N12: TRUE | O12: TRUE | P12: FALSE | Q12: COMPLETED | R12: COMPLETED | S12: COMPLETED | T12: COMPLETED | U12: COMPLETED | V12: COMPLETED | W12: COMPLETED
A13: 5 | B13: 900005 | C13: ADA Bug Bounty Website | D13: COMPLETED | E13: 55100 | F13: 55100 | G13: =E13-F13 -> 0 | H13: Steven Fisher | I13: F9: Dapps, Products & Integrations | J13: TRUE | K13: TRUE | L13: TRUE | M13: TRUE | N13: TRUE | O13: FALSE | P13: FALSE | Q13: FALSE | R13: COMPLETED | S13: COMPLETED | T13: COMPLETED | U13: COMPLETED | V13: COMPLETED | W13: COMPLETED
A14: 6 | B14: 900006 | C14: ADABET.iO | Cardano Betting DApp | D14: COMPLETED | E14: 125005 | F14: 125005 | G14: =E14-F14 -> 0 | H14: Trong | I14: F9: Dapps, Products & Integrations | J14: TRUE | K14: FALSE | L14: TRUE | M14: TRUE | N14: TRUE | O14: TRUE | P14: TRUE | Q14: TRUE | R14: TRUE | S14: TRUE | T14: TRUE | U14: TRUE | V14: FALSE | W14: COMPLETED
A15: 7 | B15: 900007 | C15: ADAO - Plutus Token Vesting DApp | D15: COMPLETED | E15: 33000 | F15: 33000 | G15: =E15-F15 -> 0 | H15: Adaminnow | I15: F9: Dapps, Products & Integrations | J15: FALSE | K15: FALSE | L15: FALSE | M15: FALSE | N15: FALSE | O15: FALSE | P15: FALSE | Q15: FALSE | R15: FALSE | S15: FALSE | T15: TRUE | U15: FALSE | V15: FALSE | W15: FALSE
A16: 8 | B16: 900008 | C16: ADAO - RoundTable v2: Staking + | D16: COMPLETED | E16: 43350 | F16: 43350 | G16: =E16-F16 -> 0 | H16: Adaminnow | I16: F9: Dapps, Products & Integrations | J16: FALSE | K16: TRUE | L16: FALSE | M16: COMPLETED | N16: COMPLETED | O16: COMPLETED | P16: COMPLETED | Q16: COMPLETED | R16: COMPLETED | S16: COMPLETED | T16: COMPLETED | U16: COMPLETED | V16: COMPLETED | W16: COMPLETED
A17: 9 | B17: 900009 | C17: ADAO- NFT Fractionalization Dapp | D17: COMPLETED | E17: 33750 | F17: 33750 | G17: =E17-F17 -> 0 | H17: Adaminnow | I17: F9: Dapps, Products & Integrations | J17: FALSE | K17: TRUE | L17: TRUE | M17: FALSE | N17: FALSE | O17: FALSE | P17: FALSE | Q17: FALSE | R17: FALSE | S17: FALSE | T17: FALSE | U17: FALSE | V17: FALSE | W17: FALSE
A18: 10 | B18: 900010 | C18: ADAO Open Source Development | D18: COMPLETED | E18: 76000 | F18: 76000 | G18: =E18-F18 -> 0 | H18: Adaminnow | I18: F9: DAOs <3 Cardano | J18: FALSE | K18: FALSE | L18: FALSE | M18: COMPLETED | N18: COMPLETED | O18: COMPLETED | P18: COMPLETED | Q18: COMPLETED | R18: COMPLETED | S18: COMPLETED | T18: COMPLETED | U18: COMPLETED | V18: COMPLETED | W18: COMPLETED
